2023-03-11 18:52:33,242 [INFO] Watching for file changes with StatReloader
2023-03-11 18:53:04,665 [INFO] C:\Users\azizz\PycharmProjects\ERPMyTrans\my_trans\views.py changed, reloading.
2023-03-11 18:53:05,842 [INFO] Watching for file changes with StatReloader
2023-03-11 18:53:23,852 [INFO] C:\Users\azizz\PycharmProjects\ERPMyTrans\my_trans\views.py changed, reloading.
2023-03-11 18:53:25,022 [INFO] Watching for file changes with StatReloader
2023-03-11 18:53:45,010 [INFO] C:\Users\azizz\PycharmProjects\ERPMyTrans\my_trans\views.py changed, reloading.
2023-03-11 18:53:46,139 [INFO] Watching for file changes with StatReloader
2023-03-11 18:54:05,199 [ERROR] Internal Server Error: /my-trans/create_mission/
Traceback (most recent call last):
  File "C:\Users\azizz\AppData\Local\Programs\Python\Python310\lib\site-packages\django\core\handlers\exception.py", line 55, in inner
    response = get_response(request)
  File "C:\Users\azizz\AppData\Local\Programs\Python\Python310\lib\site-packages\django\core\handlers\base.py", line 197, in _get_response
    response = wrapped_callback(request, *callback_args, **callback_kwargs)
  File "C:\Users\azizz\PycharmProjects\ERPMyTrans\my_trans\views.py", line 21, in create_mission
    mission.employees.add(employee['name'])
KeyError: 'name'
2023-03-11 18:55:30,834 [INFO] C:\Users\azizz\PycharmProjects\ERPMyTrans\my_trans\views.py changed, reloading.
2023-03-11 18:55:32,070 [INFO] Watching for file changes with StatReloader
2023-03-11 18:56:08,364 [WARNING] Not Found: /my-trans/list_mission/
2023-03-11 18:58:34,935 [INFO] Watching for file changes with StatReloader
2023-03-11 19:03:33,459 [INFO] C:\Users\azizz\PycharmProjects\ERPMyTrans\my_trans\views.py changed, reloading.
2023-03-11 19:03:35,844 [INFO] Watching for file changes with StatReloader
2023-03-11 19:04:03,538 [INFO] C:\Users\azizz\PycharmProjects\ERPMyTrans\my_trans\views.py changed, reloading.
2023-03-11 19:04:06,568 [INFO] Watching for file changes with StatReloader
2023-03-11 19:05:27,868 [INFO] C:\Users\azizz\PycharmProjects\ERPMyTrans\my_trans\views.py changed, reloading.
2023-03-11 19:05:31,297 [INFO] Watching for file changes with StatReloader
2023-03-11 19:07:09,019 [INFO] C:\Users\azizz\PycharmProjects\ERPMyTrans\my_trans\views.py changed, reloading.
2023-03-11 19:07:11,556 [INFO] Watching for file changes with StatReloader
2023-03-11 19:08:06,789 [ERROR] Internal Server Error: /my-trans/create_mission/
Traceback (most recent call last):
  File "C:\Users\azizz\AppData\Local\Programs\Python\Python310\lib\site-packages\django\db\models\fields\__init__.py", line 2018, in get_prep_value
    return int(value)
ValueError: invalid literal for int() with base 10: 'vbjhv'

The above exception was the direct cause of the following exception:

Traceback (most recent call last):
  File "C:\Users\azizz\AppData\Local\Programs\Python\Python310\lib\site-packages\django\core\handlers\exception.py", line 55, in inner
    response = get_response(request)
  File "C:\Users\azizz\AppData\Local\Programs\Python\Python310\lib\site-packages\django\core\handlers\base.py", line 197, in _get_response
    response = wrapped_callback(request, *callback_args, **callback_kwargs)
  File "C:\Users\azizz\PycharmProjects\ERPMyTrans\my_trans\views.py", line 22, in create_mission
    mission.employees.add(employee.get('first_name'))
  File "C:\Users\azizz\AppData\Local\Programs\Python\Python310\lib\site-packages\django\db\models\fields\related_descriptors.py", line 1070, in add
    self._add_items(
  File "C:\Users\azizz\AppData\Local\Programs\Python\Python310\lib\site-packages\django\db\models\fields\related_descriptors.py", line 1285, in _add_items
    target_ids = self._get_target_ids(target_field_name, objs)
  File "C:\Users\azizz\AppData\Local\Programs\Python\Python310\lib\site-packages\django\db\models\fields\related_descriptors.py", line 1219, in _get_target_ids
    target_ids.add(target_field.get_prep_value(obj))
  File "C:\Users\azizz\AppData\Local\Programs\Python\Python310\lib\site-packages\django\db\models\fields\related.py", line 1152, in get_prep_value
    return self.target_field.get_prep_value(value)
  File "C:\Users\azizz\AppData\Local\Programs\Python\Python310\lib\site-packages\django\db\models\fields\__init__.py", line 2020, in get_prep_value
    raise e.__class__(
ValueError: Field 'id' expected a number but got 'vbjhv'.
2023-03-11 19:11:22,003 [ERROR] Internal Server Error: /my-trans/create_mission/
Traceback (most recent call last):
  File "C:\Users\azizz\AppData\Local\Programs\Python\Python310\lib\site-packages\django\db\models\fields\__init__.py", line 2018, in get_prep_value
    return int(value)
ValueError: invalid literal for int() with base 10: 'uykru'

The above exception was the direct cause of the following exception:

Traceback (most recent call last):
  File "C:\Users\azizz\AppData\Local\Programs\Python\Python310\lib\site-packages\django\core\handlers\exception.py", line 55, in inner
    response = get_response(request)
  File "C:\Users\azizz\AppData\Local\Programs\Python\Python310\lib\site-packages\django\core\handlers\base.py", line 197, in _get_response
    response = wrapped_callback(request, *callback_args, **callback_kwargs)
  File "C:\Users\azizz\PycharmProjects\ERPMyTrans\my_trans\views.py", line 22, in create_mission
    mission.employees.add(employee.get('first_name'))
  File "C:\Users\azizz\AppData\Local\Programs\Python\Python310\lib\site-packages\django\db\models\fields\related_descriptors.py", line 1070, in add
    self._add_items(
  File "C:\Users\azizz\AppData\Local\Programs\Python\Python310\lib\site-packages\django\db\models\fields\related_descriptors.py", line 1285, in _add_items
    target_ids = self._get_target_ids(target_field_name, objs)
  File "C:\Users\azizz\AppData\Local\Programs\Python\Python310\lib\site-packages\django\db\models\fields\related_descriptors.py", line 1219, in _get_target_ids
    target_ids.add(target_field.get_prep_value(obj))
  File "C:\Users\azizz\AppData\Local\Programs\Python\Python310\lib\site-packages\django\db\models\fields\related.py", line 1152, in get_prep_value
    return self.target_field.get_prep_value(value)
  File "C:\Users\azizz\AppData\Local\Programs\Python\Python310\lib\site-packages\django\db\models\fields\__init__.py", line 2020, in get_prep_value
    raise e.__class__(
ValueError: Field 'id' expected a number but got 'uykru'.
2023-03-11 19:11:24,233 [INFO] C:\Users\azizz\PycharmProjects\ERPMyTrans\my_trans\views.py changed, reloading.
2023-03-11 19:11:26,451 [INFO] Watching for file changes with StatReloader
2023-03-11 19:11:54,374 [ERROR] Internal Server Error: /my-trans/create_mission/
Traceback (most recent call last):
  File "C:\Users\azizz\AppData\Local\Programs\Python\Python310\lib\site-packages\django\core\handlers\exception.py", line 55, in inner
    response = get_response(request)
  File "C:\Users\azizz\AppData\Local\Programs\Python\Python310\lib\site-packages\django\core\handlers\base.py", line 197, in _get_response
    response = wrapped_callback(request, *callback_args, **callback_kwargs)
  File "C:\Users\azizz\PycharmProjects\ERPMyTrans\my_trans\views.py", line 22, in create_mission
    emp = Employee.objects.get(name=full_name)
  File "C:\Users\azizz\AppData\Local\Programs\Python\Python310\lib\site-packages\django\db\models\manager.py", line 85, in manager_method
    return getattr(self.get_queryset(), name)(*args, **kwargs)
  File "C:\Users\azizz\AppData\Local\Programs\Python\Python310\lib\site-packages\django\db\models\query.py", line 636, in get
    clone = self._chain() if self.query.combinator else self.filter(*args, **kwargs)
  File "C:\Users\azizz\AppData\Local\Programs\Python\Python310\lib\site-packages\django\db\models\query.py", line 1420, in filter
    return self._filter_or_exclude(False, args, kwargs)
  File "C:\Users\azizz\AppData\Local\Programs\Python\Python310\lib\site-packages\django\db\models\query.py", line 1438, in _filter_or_exclude
    clone._filter_or_exclude_inplace(negate, args, kwargs)
  File "C:\Users\azizz\AppData\Local\Programs\Python\Python310\lib\site-packages\django\db\models\query.py", line 1445, in _filter_or_exclude_inplace
    self._query.add_q(Q(*args, **kwargs))
  File "C:\Users\azizz\AppData\Local\Programs\Python\Python310\lib\site-packages\django\db\models\sql\query.py", line 1532, in add_q
    clause, _ = self._add_q(q_object, self.used_aliases)
  File "C:\Users\azizz\AppData\Local\Programs\Python\Python310\lib\site-packages\django\db\models\sql\query.py", line 1562, in _add_q
    child_clause, needed_inner = self.build_filter(
  File "C:\Users\azizz\AppData\Local\Programs\Python\Python310\lib\site-packages\django\db\models\sql\query.py", line 1407, in build_filter
    lookups, parts, reffed_expression = self.solve_lookup_type(arg)
  File "C:\Users\azizz\AppData\Local\Programs\Python\Python310\lib\site-packages\django\db\models\sql\query.py", line 1217, in solve_lookup_type
    _, field, _, lookup_parts = self.names_to_path(lookup_splitted, self.get_meta())
  File "C:\Users\azizz\AppData\Local\Programs\Python\Python310\lib\site-packages\django\db\models\sql\query.py", line 1709, in names_to_path
    raise FieldError(
django.core.exceptions.FieldError: Cannot resolve keyword 'name' into field. Choices are: first_name, id, last_name, mission
2023-03-11 19:14:39,240 [ERROR] Internal Server Error: /my-trans/create_mission/
Traceback (most recent call last):
  File "C:\Users\azizz\AppData\Local\Programs\Python\Python310\lib\site-packages\django\core\handlers\exception.py", line 55, in inner
    response = get_response(request)
  File "C:\Users\azizz\AppData\Local\Programs\Python\Python310\lib\site-packages\django\core\handlers\base.py", line 197, in _get_response
    response = wrapped_callback(request, *callback_args, **callback_kwargs)
  File "C:\Users\azizz\PycharmProjects\ERPMyTrans\my_trans\views.py", line 22, in create_mission
    emp = Employee.objects.get(name=full_name)
  File "C:\Users\azizz\AppData\Local\Programs\Python\Python310\lib\site-packages\django\db\models\manager.py", line 85, in manager_method
    return getattr(self.get_queryset(), name)(*args, **kwargs)
  File "C:\Users\azizz\AppData\Local\Programs\Python\Python310\lib\site-packages\django\db\models\query.py", line 636, in get
    clone = self._chain() if self.query.combinator else self.filter(*args, **kwargs)
  File "C:\Users\azizz\AppData\Local\Programs\Python\Python310\lib\site-packages\django\db\models\query.py", line 1420, in filter
    return self._filter_or_exclude(False, args, kwargs)
  File "C:\Users\azizz\AppData\Local\Programs\Python\Python310\lib\site-packages\django\db\models\query.py", line 1438, in _filter_or_exclude
    clone._filter_or_exclude_inplace(negate, args, kwargs)
  File "C:\Users\azizz\AppData\Local\Programs\Python\Python310\lib\site-packages\django\db\models\query.py", line 1445, in _filter_or_exclude_inplace
    self._query.add_q(Q(*args, **kwargs))
  File "C:\Users\azizz\AppData\Local\Programs\Python\Python310\lib\site-packages\django\db\models\sql\query.py", line 1532, in add_q
    clause, _ = self._add_q(q_object, self.used_aliases)
  File "C:\Users\azizz\AppData\Local\Programs\Python\Python310\lib\site-packages\django\db\models\sql\query.py", line 1562, in _add_q
    child_clause, needed_inner = self.build_filter(
  File "C:\Users\azizz\AppData\Local\Programs\Python\Python310\lib\site-packages\django\db\models\sql\query.py", line 1407, in build_filter
    lookups, parts, reffed_expression = self.solve_lookup_type(arg)
  File "C:\Users\azizz\AppData\Local\Programs\Python\Python310\lib\site-packages\django\db\models\sql\query.py", line 1217, in solve_lookup_type
    _, field, _, lookup_parts = self.names_to_path(lookup_splitted, self.get_meta())
  File "C:\Users\azizz\AppData\Local\Programs\Python\Python310\lib\site-packages\django\db\models\sql\query.py", line 1709, in names_to_path
    raise FieldError(
django.core.exceptions.FieldError: Cannot resolve keyword 'name' into field. Choices are: first_name, id, last_name, mission
2023-03-11 19:16:03,066 [INFO] C:\Users\azizz\PycharmProjects\ERPMyTrans\my_trans\views.py changed, reloading.
2023-03-11 19:16:05,437 [INFO] Watching for file changes with StatReloader
2023-03-11 19:16:36,653 [ERROR] Internal Server Error: /my-trans/create_mission/
Traceback (most recent call last):
  File "C:\Users\azizz\AppData\Local\Programs\Python\Python310\lib\site-packages\django\core\handlers\exception.py", line 55, in inner
    response = get_response(request)
  File "C:\Users\azizz\AppData\Local\Programs\Python\Python310\lib\site-packages\django\core\handlers\base.py", line 197, in _get_response
    response = wrapped_callback(request, *callback_args, **callback_kwargs)
  File "C:\Users\azizz\PycharmProjects\ERPMyTrans\my_trans\views.py", line 23, in create_mission
    emp = Employee.objects.get(first_name=employee['first_name'], last_name=employee['last_name'])
  File "C:\Users\azizz\AppData\Local\Programs\Python\Python310\lib\site-packages\django\db\models\manager.py", line 85, in manager_method
    return getattr(self.get_queryset(), name)(*args, **kwargs)
  File "C:\Users\azizz\AppData\Local\Programs\Python\Python310\lib\site-packages\django\db\models\query.py", line 650, in get
    raise self.model.DoesNotExist(
my_trans.models.Employee.DoesNotExist: Employee matching query does not exist.
2023-03-11 19:17:13,341 [INFO] Watching for file changes with StatReloader
2023-03-11 19:17:59,561 [ERROR] Internal Server Error: /my-trans/create_mission/
Traceback (most recent call last):
  File "C:\Users\azizz\AppData\Local\Programs\Python\Python310\lib\site-packages\django\core\handlers\exception.py", line 55, in inner
    response = get_response(request)
  File "C:\Users\azizz\AppData\Local\Programs\Python\Python310\lib\site-packages\django\core\handlers\base.py", line 197, in _get_response
    response = wrapped_callback(request, *callback_args, **callback_kwargs)
  File "C:\Users\azizz\PycharmProjects\ERPMyTrans\my_trans\views.py", line 23, in create_mission
    emp = Employee.objects.get(first_name=employee['first_name'], last_name=employee['last_name'])
  File "C:\Users\azizz\AppData\Local\Programs\Python\Python310\lib\site-packages\django\db\models\manager.py", line 85, in manager_method
    return getattr(self.get_queryset(), name)(*args, **kwargs)
  File "C:\Users\azizz\AppData\Local\Programs\Python\Python310\lib\site-packages\django\db\models\query.py", line 650, in get
    raise self.model.DoesNotExist(
my_trans.models.Employee.DoesNotExist: Employee matching query does not exist.
2023-03-11 19:18:07,204 [INFO] C:\Users\azizz\PycharmProjects\ERPMyTrans\my_trans\views.py changed, reloading.
2023-03-11 19:18:09,380 [INFO] Watching for file changes with StatReloader
2023-03-11 19:19:34,546 [WARNING] Not Found: /my-trans/list_employee/
2023-03-11 19:22:49,380 [DEBUG] Using proactor: IocpProactor
2023-03-11 19:26:03,026 [INFO] C:\Users\azizz\PycharmProjects\ERPMyTrans\my_trans\forms.py changed, reloading.
2023-03-11 19:26:05,155 [INFO] Watching for file changes with StatReloader
2023-03-11 19:27:06,412 [INFO] C:\Users\azizz\PycharmProjects\ERPMyTrans\my_trans\forms.py changed, reloading.
2023-03-11 19:27:08,523 [INFO] Watching for file changes with StatReloader
2023-03-11 19:28:59,927 [INFO] Watching for file changes with StatReloader
2023-03-18 15:01:50,745 [INFO] Watching for file changes with StatReloader
2023-03-18 15:02:13,873 [WARNING] Not Found: /
2023-03-18 15:02:15,080 [WARNING] Not Found: /favicon.ico
2023-03-18 15:07:27,323 [ERROR] Internal Server Error: /my-trans/create_mission/
Traceback (most recent call last):
  File "C:\Users\azizz\AppData\Local\Programs\Python\Python310\lib\site-packages\django\core\handlers\exception.py", line 55, in inner
    response = get_response(request)
  File "C:\Users\azizz\AppData\Local\Programs\Python\Python310\lib\site-packages\django\core\handlers\base.py", line 197, in _get_response
    response = wrapped_callback(request, *callback_args, **callback_kwargs)
  File "C:\Users\azizz\PycharmProjects\ERPMyTrans\my_trans\views.py", line 34, in create_mission
    return render(request, "create_mission.html", context)
  File "C:\Users\azizz\AppData\Local\Programs\Python\Python310\lib\site-packages\django\shortcuts.py", line 24, in render
    content = loader.render_to_string(template_name, context, request, using=using)
  File "C:\Users\azizz\AppData\Local\Programs\Python\Python310\lib\site-packages\django\template\loader.py", line 61, in render_to_string
    template = get_template(template_name, using=using)
  File "C:\Users\azizz\AppData\Local\Programs\Python\Python310\lib\site-packages\django\template\loader.py", line 15, in get_template
    return engine.get_template(template_name)
  File "C:\Users\azizz\AppData\Local\Programs\Python\Python310\lib\site-packages\django\template\backends\django.py", line 34, in get_template
    return Template(self.engine.get_template(template_name), self)
  File "C:\Users\azizz\AppData\Local\Programs\Python\Python310\lib\site-packages\django\template\engine.py", line 175, in get_template
    template, origin = self.find_template(template_name)
  File "C:\Users\azizz\AppData\Local\Programs\Python\Python310\lib\site-packages\django\template\engine.py", line 157, in find_template
    template = loader.get_template(name, skip=skip)
  File "C:\Users\azizz\AppData\Local\Programs\Python\Python310\lib\site-packages\django\template\loaders\cached.py", line 57, in get_template
    template = super().get_template(template_name, skip)
  File "C:\Users\azizz\AppData\Local\Programs\Python\Python310\lib\site-packages\django\template\loaders\base.py", line 28, in get_template
    return Template(
  File "C:\Users\azizz\AppData\Local\Programs\Python\Python310\lib\site-packages\django\template\base.py", line 154, in __init__
    self.nodelist = self.compile_nodelist()
  File "C:\Users\azizz\AppData\Local\Programs\Python\Python310\lib\site-packages\django\template\base.py", line 200, in compile_nodelist
    return parser.parse()
  File "C:\Users\azizz\AppData\Local\Programs\Python\Python310\lib\site-packages\django\template\base.py", line 513, in parse
    raise self.error(token, e)
  File "C:\Users\azizz\AppData\Local\Programs\Python\Python310\lib\site-packages\django\template\base.py", line 511, in parse
    compiled_result = compile_func(self, token)
  File "C:\Users\azizz\AppData\Local\Programs\Python\Python310\lib\site-packages\django\template\loader_tags.py", line 293, in do_extends
    nodelist = parser.parse()
  File "C:\Users\azizz\AppData\Local\Programs\Python\Python310\lib\site-packages\django\template\base.py", line 513, in parse
    raise self.error(token, e)
  File "C:\Users\azizz\AppData\Local\Programs\Python\Python310\lib\site-packages\django\template\base.py", line 511, in parse
    compiled_result = compile_func(self, token)
  File "C:\Users\azizz\AppData\Local\Programs\Python\Python310\lib\site-packages\django\template\loader_tags.py", line 232, in do_block
    nodelist = parser.parse(("endblock",))
  File "C:\Users\azizz\AppData\Local\Programs\Python\Python310\lib\site-packages\django\template\base.py", line 518, in parse
    self.unclosed_block_tag(parse_until)
  File "C:\Users\azizz\AppData\Local\Programs\Python\Python310\lib\site-packages\django\template\base.py", line 581, in unclosed_block_tag
    raise self.error(token, msg)
django.template.exceptions.TemplateSyntaxError: Unclosed tag on line 3: 'block'. Looking for one of: endblock.
